Workbook
Name budget: 'Budget Dashboard'!$L1
Name budget_range: 'Budget Dashboard'!$Q1
Name budget_rank: 'Budget Dashboard'!$R1
Name categorized_transactions: SOURCE!$A$432:$D$531
Name categorized_transactions_1: SOURCE!$A$1:$D$217
Name categorized_transactions_2: SOURCE!$I$1:$L$219
Name categorized_transactions_3: SOURCE!$A$218:$D$302
Name categorized_transactions_4: SOURCE!$A$303:$D$431
Name cc_budget: Calculations!$K1
Name cc_delta: Calculations!$L1
Name cc_in_focus: Calculations!$G1
Name cc_month_number: Calculations!$F1
Name cc_show_remaining_budget: Calculations!$I1
Name cc_show_type: Calculations!$H1
Name cc_tracked: Calculations!$J1
Name cc_type: Calculations!$E1
Name comb_rank: 'Budget Dashboard'!$S1
Name comb_rank_norm: 'Budget Dashboard'!$U1
Name comb_rank_norm_run_range: 'Budget Dashboard'!$V1
Name comb_rank_range: 'Budget Dashboard'!$T1
Name comb_rank_unique: 'Budget Dashboard'!$W1
Name current_date: DATE(2025,3,15)
Name expenses_header_row: ROW(Expenses[[#Headers],[Expenses]])
Name expenses_max_row: MAX(ROW(Expenses[]))
Name expenses_min_row: MIN(ROW(Expenses[]))
Name expenses_total_row: ROW('Budget Planning'!$C$52)
Name header_row_id: 'Budget Dashboard'!$D1
Name income_header_row: ROW(Income[[#Headers],[Income]])
Name income_max_row: MAX(ROW(Income[]))
Name income_min_row: MIN(ROW(Income[]))
Name income_total_row: ROW('Budget Planning'!$C$24)
Name is_cat: 'Budget Dashboard'!$F1
Name is_empty: 'Budget Dashboard'!$H1
Name is_header: 'Budget Dashboard'!$E1
Name is_total: 'Budget Dashboard'!$G1
Name item: 'Budget Dashboard'!$J1
Name out_budget: 'Budget Dashboard'!$AA1
Name out_percentage_completed: 'Budget Dashboard'!$AB1
Name out_tracked: 'Budget Dashboard'!$Z1
Name row_id: 'Budget Dashboard'!$C1
Name savings_header_row: ROW(Savings[[#Headers],[Savings]])
Name savings_max_row: MAX(ROW(Savings[]))
Name savings_min_row: MIN(ROW(Savings[]))
Name savings_total_row: ROW('Budget Planning'!$C$66)
Name selected_period: Calculations!$E$20
Name selected_period_display: Calculations!$E$21
Name selected_year: Calculations!$E$19
Name shift_late_income_starting_date: Settings!$E$18
Name shift_late_income_status: Settings!$E$16
Name Slicer_Category: #N/A
Name sort_max_row: 'Budget Dashboard'!$N1
Name sort_min_row: 'Budget Dashboard'!$M1
Name starting_year: Settings!$E$8
Name tracked: 'Budget Dashboard'!$K1
Name tracked_range: 'Budget Dashboard'!$O1
Name tracked_rank: 'Budget Dashboard'!$P1
Name type: 'Budget Dashboard'!$I1

Sheet Notes & Logs
A1: Step by Step Updating Process
A3: 1. Go to Source > Check latest transactions
A4: 2. Go to Ebanking > Extract cc_invoice + ubs_transactions
A5: 3. Move files from download to raw_ds
A6: 4. Run script in > Lucas_Sandbox_Budget_Script
A7: 5. Select next cell from last row in Source and import output.csv file
A8: 6. Check & Label
A9: 7. Budget Tracking > drag table
A10: 8. Budget Planning Compute Diff for extra savings
A11: 9. Expenses_Add update rows (drag) + pivot

Sheet SOURCE
A1: date | B1: Type | C1: Category | D1: Amount | E1: abs_Amount | I1: date | J1: Type | K1: Category | L1: Amount | O1: Income
A2: 45870 | B2: Expenses | C2: Digital Goods | D2: -0.05 | E2: =ABS(D2) -> 0.05 | I2: 45870 | J2: No-Label | K2: digital goods - google cloud mwgb4h dublin irl [CC] | L2: -0.05 | O2: Employment
A3: 45870 | B3: Expenses | C3: Train | D3: -18 | E3: =ABS(D3) -> 18 | I3: 45870 | J3: Expenses | K3: Train | L3: -18 | O3: Side Hustle
A4: 45870 | B4: Expenses | C4: Restaurants | D4: -13.5 | E4: =ABS(D4) -> 13.5 | I4: 45870 | J4: Expenses | K4: coop pronto nyon;1260 nyon [UBS] | L4: -13.5 | O4: Extras / Twint Chargeback
A5: 45870 | B5: Expenses | C5: Train | D5: -4.7 | E5: =ABS(D5) -> 4.7 | I5: 45870 | J5: Expenses | K5: Train | L5: -4.7 | O5: Enter income Category…
A6: 45870 | B6: Expenses | C6: Train | D6: -3.9 | E6: =ABS(D6) -> 3.9 | I6: 45870 | J6: Expenses | K6: Train | L6: -3.9 | O6: Enter income Category…
A7: 45872 | B7: Expenses | C7: Car | D7: -49.11 | E7: =ABS(D7) -> 49.11 | I7: 45901 | J7: Expenses | K7: Groceries | L7: -1.65 | O7: Enter income Category…
A8: 45872 | B8: Income | C8: Extras / Twint Chargeback | D8: 44 | E8: =ABS(D8) -> 44 | I8: 45901 | J8: Expenses | K8: Train | L8: -4.7 | O8: Enter income Category…
A9: 45873 | B9: Expenses | C9: Train | D9: -4.7 | E9: =ABS(D9) -> 4.7 | I9: 45901 | J9: Expenses | K9: Train | L9: -4.7 | O9: Enter income Category…
A10: 45873 | B10: Expenses | C10: Restaurants | D10: -31.5 | E10: =ABS(D10) -> 31.5 | I10: 45901 | J10: CC_Refund | K10: Card Refund Luca | L10: -726.2 | O10: Enter income Category…
A11: 45874 | B11: Expenses | C11: Restaurants | D11: -8 | E11: =ABS(D11) -> 8 | I11: 45901 | J11: Expenses | K11: Train | L11: -3.6 | O11: Enter income Category…
A12: 45874 | B12: Expenses | C12: Train | D12: -4.7 | E12: =ABS(D12) -> 4.7 | I12: 45901 | J12: No-Label | K12: data processing services - google cloud mjvxr6 dublin irl [CC] | L12: -0.01 | O12: Total
A13: 45875 | B13: Expenses | C13: Groceries | D13: -9.5 | E13: =ABS(D13) -> 9.5 | I13: 45901 | J13: Expenses | K13: Restaurants | L13: -18.9
A14: 45875 | B14: Expenses | C14: Train | D14: -4.7 | E14: =ABS(D14) -> 4.7 | I14: 45901 | J14: Expenses | K14: Groceries | L14: -3.8 | O14: Expenses
A15: 45875 | B15: Expenses | C15: Train | D15: -4.7 | E15: =ABS(D15) -> 4.7 | I15: 45902 | J15: Expenses | K15: Train | L15: -4.7 | O15: Housing
A16: 45876 | B16: Expenses | C16: Wellbeing | D16: -10 | E16: =ABS(D16) -> 10 | I16: 45902 | J16: Expenses | K16: assura-basis sa;1009 pully; ch [UBS] | L16: -501.35 | O16: Home Utils
A17: 45876 | B17: Expenses | C17: Train | D17: -7.8 | E17: =ABS(D17) -> 7.8 | I17: 45872 | J17: Expenses | K17: Car | L17: -49.11 | O17: Groceries
A18: 45876 | B18: Expenses | C18: Groceries | D18: -40.35 | E18: =ABS(D18) -> 40.35 | I18: 45872 | J18: Income | K18: Extras / Twint Chargeback | L18: 44 | O18: Restaurants
A19: 45876 | B19: Expenses | C19: Digital Goods | D19: -7 | E19: =ABS(D19) -> 7 | I19: 45903 | J19: Expenses | K19: Restaurants | L19: -18 | O19: Train
A20: 45876 | B20: Expenses | C20: Restaurants | D20: -8.2 | E20: =ABS(D20) -> 8.2 | I20: 45873 | J20: Expenses | K20: Train | L20: -4.7 | O20: Internet + Mobile
A21: 45876 | B21: Expenses | C21: Restaurants | D21: -14 | E21: =ABS(D21) -> 14 | I21: 45873 | J21: Expenses | K21: , eldrick; debit ubs twint [UBS] | L21: -31.5 | O21: Car
A22: 45877 | B22: Expenses | C22: Internet + Mobile | D22: -49 | E22: =ABS(D22) -> 49 | I22: 45904 | J22: Expenses | K22: Train | L22: -4.7 | O22: Health Insurance
A23: 45877 | B23: Expenses | C23: Internet + Mobile | D23: -28.85 | E23: =ABS(D23) -> 28.85 | I23: 45904 | J23: Expenses | K23: Health Other | L23: -9.2 | O23: Health Other
A24: 45877 | B24: Expenses | C24: Groceries | D24: -4.9 | E24: =ABS(D24) -> 4.9 | I24: 45904 | J24: Expenses | K24: Groceries | L24: -3.1 | O24: Clothing
A25: 45877 | B25: Expenses | C25: Restaurants | D25: -15.5 | E25: =ABS(D25) -> 15.5 | I25: 45904 | J25: Expenses | K25: grossmann, dany; debit ubs twint [UBS] | L25: -150 | O25: Media
... A39: 45882 | B39: Income | C39: Side Hustle | D39: 1465.3 | E39: =ABS(D39) -> 1465.3 | I39: 45876 | J39: No-Label | K39: computer software stores - heroku* jul-107212674 san franciscousaca [CC] | L39: -7 | O39: Total
A40: 45882 | B40: Income | C40: Side Hustle | D40: 852 | E40: =ABS(D40) -> 852 | I40: 45876 | J40: Expenses | K40: tabac du rhone;1205 geneve [UBS] | L40: -8.2
A41: 45882 | B41: Income | C41: Side Hustle | D41: 400 | E41: =ABS(D41) -> 400 | I41: 45876 | J41: Expenses | K41: ls lavandieres;1204 geneve [UBS] | L41: -14 | O41: Savings
A42: 45882 | B42: Income | C42: Side Hustle | D42: 320 | E42: =ABS(D42) -> 320 | I42: 45907 | J42: Expenses | K42: Train | L42: -4.7 | O42: Emergency Fund
A43: 45882 | B43: Income | C43: Side Hustle | D43: 320 | E43: =ABS(D43) -> 320 | I43: 45907 | J43: Expenses | K43: lavorent; payment ubs twint [UBS] | L43: -55 | O43: Retirement Account
A44: 45882 | B44: Expenses | C44: Groceries | D44: -25.9 | E44: =ABS(D44) -> 25.9 | I44: 45907 | J44: Expenses | K44: Groceries | L44: -1.95 | O44: Stock Portofolio
A45: 45883 | B45: Expenses | C45: Train | D45: -4.7 | E45: =ABS(D45) -> 4.7 | I45: 45907 | J45: Expenses | K45: Train | L45: -4.7 | O45: Sinking Fund Dow Payment
A46: 45883 | B46: Expenses | C46: Train | D46: -4.7 | E46: =ABS(D46) -> 4.7 | I46: 45877 | J46: Expenses | K46: swisscom (schweiz) ag /; payment ubs twint [UBS] | L46: -49 | O46: Sinking Fund Rest
A47: 45883 | B47: Expenses | C47: Car | D47: -9.75 | E47: =ABS(D47) -> 9.75 | I47: 45877 | J47: Expenses | K47: swisscom (schweiz) ag /; payment ubs twint [UBS] | L47: -28.85 | O47: Enter Savings Category…
A48: 45884 | B48: Expenses | C48: Groceries | D48: -10.1 | E48: =ABS(D48) -> 10.1 | I48: 45877 | J48: Expenses | K48: migros mm jonction;1205 gen√®ve [UBS] | L48: -4.9 | O48: Enter Savings Category…
A49: 45884 | B49: Expenses | C49: Restaurants | D49: -33 | E49: =ABS(D49) -> 33 | I49: 45877 | J49: Expenses | K49: Restaurants | L49: -15.5 | O49: Enter Savings Category…
A50: 45884 | B50: Expenses | C50: Restaurants | D50: -21 | E50: =ABS(D50) -> 21 | I50: 45877 | J50: Income | K50: Extras / Twint Chargeback | L50: 30 | O50: Enter Savings Category…
A51: 45884 | B51: Expenses | C51: Digital Goods | D51: -26.6 | E51: =ABS(D51) -> 26.6 | I51: 45877 | J51: Income | K51: Side Hustle | L51: 4 | O51: Enter Savings Category…
A52: 45885 | B52: Expenses | C52: Train | D52: -4.7 | E52: =ABS(D52) -> 4.7 | I52: 45877 | J52: Expenses | K52: Train | L52: -4.7 | O52: Total
A53: 45885 | B53: Expenses | C53: Train | D53: -4.7 | E53: =ABS(D53) -> 4.7 | I53: 45877 | J53: Expenses | K53: Restaurants | L53: -32
...

Sheet Settings
C2: Settings
C6: General
D8: Starting Year: | E8: 2025 | G8: Set the starting year (yyyy) once at the beginning and do not change it
C12: Budget Tracking & Dashboard
D14: Late Monthly Income
D16: Shift late income: | E16: Inactive | G16: Activate this option to treat late income received on or after a certain day of the month as income for the next month. This is especially recommended in case you receive your monthly paycheck towards the end of the month and prefer to consider this income as the disposable income for the next month
D18: Starting on day x in month: | E18: 25
D29: Video | E29: https://www.youtube.com/watch?v=eKyAOjH3Crk

Sheet Budget Planning
C2: Budget Planning
C4: Savings | Q4: =Q24-Q52 -> 15415.6 | AE4: =AE24-AE52 -> 46633.08
C5: Ratio | Q5: =Q52/Q24 -> 0.67600639 | AE5: =AE52/AE24 -> 0.52637538
C6: Define starting year in Settings → | E6: =starting_year -> 2025 | S6: =E6 + 1 -> 2026 | AG6: =S6 + 1 -> 2027 | AU6: =AG6 + 1 -> 2028 | BI6: =AU6 + 1 -> 2029 | BW6: =BI6 + 1 -> 2030 | CK6: =BW6 + 1 -> 2031 | CY6: =CK6 + 1 -> 2032 | DM6: =CY6 + 1 -> 2033 | EA6: =DM6 + 1 -> 2034 | EO6: =EA6 + 1 -> 2035 | FC6: =EO6 + 1 -> 2036 | FQ6: =FC6 + 1 -> 2037 | GE6: =FQ6 + 1 -> 2038 | GS6: =GE6 + 1 -> 2039 | HG6: =GS6 + 1 -> 2040 | HU6: =HG6 + 1 -> 2041
E7: =IF(E8=0,"Jan ✓", "Jan") -> Jan ✓ | F7: =IF(F8=0,"Feb ✓", "Feb") -> Feb ✓ | G7: =IF(G8=0,"Mar ✓", "Mar") -> Mar ✓ | H7: =IF(H8=0,"Apr ✓", "Apr") -> Apr ✓ | I7: =IF(I8=0,"May ✓", "May") -> May ✓ | J7: =IF(J8=0,"Jun ✓", "Jun") -> Jun ✓ | K7: =IF(K8=0,"Jul ✓", "Jul") -> Jul ✓ | L7: =IF(L8=0,"Aug ✓", "Aug") -> Aug | M7: =IF(M8=0,"Sep ✓", "Sep") -> Sep | N7: =IF(N8=0,"Oct ✓", "Oct") -> Oct | O7: =IF(O8=0,"Nov ✓", "Nov") -> Nov | P7: =IF(P8=0,"Dec ✓", "Dec") -> Dec | Q7: =IF(Q8=0,"Total ✓", "Total") -> Total | S7: =IF(S8=0,"Jan ✓", "Jan") -> Jan | T7: =IF(T8=0,"Feb ✓", "Feb") -> Feb | U7: =IF(U8=0,"Mar ✓", "Mar") -> Mar | V7: =IF(V8=0,"Apr ✓", "Apr") -> Apr | W7: =IF(W8=0,"May ✓", "May") -> May | X7: =IF(X8=0,"Jun ✓", "Jun") -> Jun | Y7: =IF(Y8=0,"Jul ✓", "Jul") -> Jul | Z7: =IF(Z8=0,"Aug ✓", "Aug") -> Aug | AA7: =IF(AA8=0,"Sep ✓", "Sep") -> Sep | AB7: =IF(AB8=0,"Oct ✓", "Oct") -> Oct | AC7: =IF(AC8=0,"Nov ✓", "Nov") -> Nov | AD7: =IF(AD8=0,"Dec ✓", "Dec") -> Dec | AE7: =IF(AE8=0,"Total ✓", "Total") -> Total | AG7: =IF(AG8=0,"Jan ✓", "Jan") -> Jan ✓ | AH7: =IF(AH8=0,"Feb ✓", "Feb") -> Feb ✓ | AI7: =IF(AI8=0,"Mar ✓", "Mar") -> Mar ✓ | AJ7: =IF(AJ8=0,"Apr ✓", "Apr") -> Apr ✓ | AK7: =IF(AK8=0,"May ✓", "May") -> May ✓ | AL7: =IF(AL8=0,"Jun ✓", "Jun") -> Jun ✓ | AM7: =IF(AM8=0,"Jul ✓", "Jul") -> Jul ✓ | AN7: =IF(AN8=0,"Aug ✓", "Aug") -> Aug ✓ | AO7: =IF(AO8=0,"Sep ✓", "Sep") -> Sep ✓ | AP7: =IF(AP8=0,"Oct ✓", "Oct") -> Oct ✓ | AQ7: =IF(AQ8=0,"Nov ✓", "Nov") -> Nov ✓ | AR7: =IF(AR8=0,"Dec ✓", "Dec") -> Dec ✓ | AS7: =IF(AS8=0,"Total ✓", "Total") -> Total ✓ | AU7: =IF(AU8=0,"Jan ✓", "Jan") -> Jan ✓ | AV7: =IF(AV8=0,"Feb ✓", "Feb") -> Feb ✓ | AW7: =IF(AW8=0,"Mar ✓", "Mar") -> Mar ✓ | AX7: =IF(AX8=0,"Apr ✓", "Apr") -> Apr ✓ | AY7: =IF(AY8=0,"May ✓", "May") -> May ✓ | AZ7: =IF(AZ8=0,"Jun ✓", "Jun") -> Jun ✓ | BA7: =IF(BA8=0,"Jul ✓", "Jul") -> Jul ✓ | BB7: =IF(BB8=0,"Aug ✓", "Aug") -> Aug ✓ | BC7: =IF(BC8=0,"Sep ✓", "Sep") -> Sep ✓ | BD7: =IF(BD8=0,"Oct ✓", "Oct") -> Oct ✓ | BE7: =IF(BE8=0,"Nov ✓", "Nov") -> Nov ✓ | BF7: =IF(BF8=0,"Dec ✓", "Dec") -> Dec ✓ | BG7: =IF(BG8=0,"Total ✓", "Total") -> Total ✓ | BI7: =IF(BI8=0,"Jan ✓", "Jan") -> Jan ✓ | BJ7: =IF(BJ8=0,"Feb ✓", "Feb") -> Feb ✓ | BK7: =IF(BK8=0,"Mar ✓", "Mar") -> Mar ✓ | BL7: =IF(BL8=0,"Apr ✓", "Apr") -> Apr ✓ | BM7: =IF(BM8=0,"May ✓", "May") -> May ✓ | BN7: =IF(BN8=0,"Jun ✓", "Jun") -> Jun ✓ | BO7: =IF(BO8=0,"Jul ✓", "Jul") -> Jul ✓ | BP7: =IF(BP8=0,"Aug ✓", "Aug") -> Aug ✓ | BQ7: =IF(BQ8=0,"Sep ✓", "Sep") -> Sep ✓ | BR7: =IF(BR8=0,"Oct ✓", "Oct") -> Oct ✓ | BS7: =IF(BS8=0,"Nov ✓", "Nov") -> Nov ✓ | BT7: =IF(BT8=0,"Dec ✓", "Dec") -> Dec ✓ | BU7: =IF(BU8=0,"Total ✓", "Total") -> Total ✓ | BW7: =IF(BW8=0,"Jan ✓", "Jan") -> Jan ✓ | BX7: =IF(BX8=0,"Feb ✓", "Feb") -> Feb ✓ | BY7: =IF(BY8=0,"Mar ✓", "Mar") -> Mar ✓ | BZ7: =IF(BZ8=0,"Apr ✓", "Apr") -> Apr ✓ | CA7: =IF(CA8=0,"May ✓", "May") -> May ✓ | CB7: =IF(CB8=0,"Jun ✓", "Jun") -> Jun ✓ | CC7: =IF(CC8=0,"Jul ✓", "Jul") -> Jul ✓ | CD7: =IF(CD8=0,"Aug ✓", "Aug") -> Aug ✓ | CE7: =IF(CE8=0,"Sep ✓", "Sep") -> Sep ✓ | CF7: =IF(CF8=0,"Oct ✓", "Oct") -> Oct ✓ | CG7: =IF(CG8=0,"Nov ✓", "Nov") -> Nov ✓ | CH7: =IF(CH8=0,"Dec ✓", "Dec") -> Dec ✓ | CI7: =IF(CI8=0,"Total ✓", "Total") -> Total ✓ | CK7: =IF(CK8=0,"Jan ✓", "Jan") -> Jan ✓ | CL7: =IF(CL8=0,"Feb ✓", "Feb") -> Feb ✓ | CM7: =IF(CM8=0,"Mar ✓", "Mar") -> Mar ✓ | CN7: =IF(CN8=0,"Apr ✓", "Apr") -> Apr ✓ | CO7: =IF(CO8=0,"May ✓", "May") -> May ✓ | CP7: =IF(CP8=0,"Jun ✓", "Jun") -> Jun ✓ | CQ7: =IF(CQ8=0,"Jul ✓", "Jul") -> Jul ✓ | CR7: =IF(CR8=0,"Aug ✓", "Aug") -> Aug ✓ | CS7: =IF(CS8=0,"Sep ✓", "Sep") -> Sep ✓ | CT7: =IF(CT8=0,"Oct ✓", "Oct") -> Oct ✓ | CU7: =IF(CU8=0,"Nov ✓", "Nov") -> Nov ✓ | CV7: =IF(CV8=0,"Dec ✓", "Dec") -> Dec ✓ | CW7: =IF(CW8=0,"Total ✓", "Total") -> Total ✓ | CY7: =IF(CY8=0,"Jan ✓", "Jan") -> Jan ✓ | CZ7: =IF(CZ8=0,"Feb ✓", "Feb") -> Feb ✓ | DA7: =IF(DA8=0,"Mar ✓", "Mar") -> Mar ✓ | DB7: =IF(DB8=0,"Apr ✓", "Apr") -> Apr ✓ | DC7: =IF(DC8=0,"May ✓", "May") -> May ✓ | DD7: =IF(DD8=0,"Jun ✓", "Jun") -> Jun ✓ | DE7: =IF(DE8=0,"Jul ✓", "Jul") -> Jul ✓ | DF7: =IF(DF8=0,"Aug ✓", "Aug") -> Aug ✓ | DG7: =IF(DG8=0,"Sep ✓", "Sep") -> Sep ✓ | DH7: =IF(DH8=0,"Oct ✓", "Oct") -> Oct ✓ | DI7: =IF(DI8=0,"Nov ✓", "Nov") -> Nov ✓ | DJ7: =IF(DJ8=0,"Dec ✓", "Dec") -> Dec ✓ | DK7: =IF(DK8=0,"Total ✓", "Total") -> Total ✓ | DM7: =IF(DM8=0,"Jan ✓", "Jan") -> Jan ✓ | DN7: =IF(DN8=0,"Feb ✓", "Feb") -> Feb ✓ | DO7: =IF(DO8=0,"Mar ✓", "Mar") -> Mar ✓ | DP7: =IF(DP8=0,"Apr ✓", "Apr") -> Apr ✓ | DQ7: =IF(DQ8=0,"May ✓", "May") -> May ✓ | DR7: =IF(DR8=0,"Jun ✓", "Jun") -> Jun ✓ | DS7: =IF(DS8=0,"Jul ✓", "Jul") -> Jul ✓ | DT7: =IF(DT8=0,"Aug ✓", "Aug") -> Aug ✓ | DU7: =IF(DU8=0,"Sep ✓", "Sep") -> Sep ✓ | DV7: =IF(DV8=0,"Oct ✓", "Oct") -> Oct ✓ | DW7: =IF(DW8=0,"Nov ✓", "Nov") -> Nov ✓ | DX7: =IF(DX8=0,"Dec ✓", "Dec") -> Dec ✓ | DY7: =IF(DY8=0,"Total ✓", "Total") -> Total ✓ | EA7: =IF(EA8=0,"Jan ✓", "Jan") -> Jan ✓ | EB7: =IF(EB8=0,"Feb ✓", "Feb") -> Feb ✓ | EC7: =IF(EC8=0,"Mar ✓", "Mar") -> Mar ✓ | ED7: =IF(ED8=0,"Apr ✓", "Apr") -> Apr ✓ | EE7: =IF(EE8=0,"May ✓", "May") -> May ✓ | EF7: =IF(EF8=0,"Jun ✓", "Jun") -> Jun ✓ | EG7: =IF(EG8=0,"Jul ✓", "Jul") -> Jul ✓ | EH7: =IF(EH8=0,"Aug ✓", "Aug") -> Aug ✓ | EI7: =IF(EI8=0,"Sep ✓", "Sep") -> Sep ✓ | EJ7: =IF(EJ8=0,"Oct ✓", "Oct") -> Oct ✓ | EK7: =IF(EK8=0,"Nov ✓", "Nov") -> Nov ✓ | EL7: =IF(EL8=0,"Dec ✓", "Dec") -> Dec ✓ | EM7: =IF(EM8=0,"Total ✓", "Total") -> Total ✓ | EO7: =IF(EO8=0,"Jan ✓", "Jan") -> Jan ✓ | EP7: =IF(EP8=0,"Feb ✓", "Feb") -> Feb ✓ | EQ7: =IF(EQ8=0,"Mar ✓", "Mar") -> Mar ✓ | ER7: =IF(ER8=0,"Apr ✓", "Apr") -> Apr ✓ | ES7: =IF(ES8=0,"May ✓", "May") -> May ✓ | ET7: =IF(ET8=0,"Jun ✓", "Jun") -> Jun ✓ | EU7: =IF(EU8=0,"Jul ✓", "Jul") -> Jul ✓ | EV7: =IF(EV8=0,"Aug ✓", "Aug") -> Aug ✓ | EW7: =IF(EW8=0,"Sep ✓", "Sep") -> Sep ✓ | EX7: =IF(EX8=0,"Oct ✓", "Oct") -> Oct ✓ | EY7: =IF(EY8=0,"Nov ✓", "Nov") -> Nov ✓ | EZ7: =IF(EZ8=0,"Dec ✓", "Dec") -> Dec ✓ | FA7: =IF(FA8=0,"Total ✓", "Total") -> Total ✓ | FC7: =IF(FC8=0,"Jan ✓", "Jan") -> Jan ✓ | FD7: =IF(FD8=0,"Feb ✓", "Feb") -> Feb ✓ | FE7: =IF(FE8=0,"Mar ✓", "Mar") -> Mar ✓ | FF7: =IF(FF8=0,"Apr ✓", "Apr") -> Apr ✓ | FG7: =IF(FG8=0,"May ✓", "May") -> May ✓ | FH7: =IF(FH8=0,"Jun ✓", "Jun") -> Jun ✓ | FI7: =IF(FI8=0,"Jul ✓", "Jul") -> Jul ✓ | FJ7: =IF(FJ8=0,"Aug ✓", "Aug") -> Aug ✓ | FK7: =IF(FK8=0,"Sep ✓", "Sep") -> Sep ✓ | FL7: =IF(FL8=0,"Oct ✓", "Oct") -> Oct ✓ | FM7: =IF(FM8=0,"Nov ✓", "Nov") -> Nov ✓ | FN7: =IF(FN8=0,"Dec ✓", "Dec") -> Dec ✓ | FO7: =IF(FO8=0,"Total ✓", "Total") -> Total ✓ | FQ7: =IF(FQ8=0,"Jan ✓", "Jan") -> Jan ✓ | FR7: =IF(FR8=0,"Feb ✓", "Feb") -> Feb ✓ | FS7: =IF(FS8=0,"Mar ✓", "Mar") -> Mar ✓ | FT7: =IF(FT8=0,"Apr ✓", "Apr") -> Apr ✓ | FU7: =IF(FU8=0,"May ✓", "May") -> May ✓ | FV7: =IF(FV8=0,"Jun ✓", "Jun") -> Jun ✓ | FW7: =IF(FW8=0,"Jul ✓", "Jul") -> Jul ✓ | FX7: =IF(FX8=0,"Aug ✓", "Aug") -> Aug ✓ | FY7: =IF(FY8=0,"Sep ✓", "Sep") -> Sep ✓ | FZ7: =IF(FZ8=0,"Oct ✓", "Oct") -> Oct ✓ | GA7: =IF(GA8=0,"Nov ✓", "Nov") -> Nov ✓ | GB7: =IF(GB8=0,"Dec ✓", "Dec") -> Dec ✓ | GC7: =IF(GC8=0,"Total ✓", "Total") -> Total ✓ | GE7: =IF(GE8=0,"Jan ✓", "Jan") -> Jan ✓ | GF7: =IF(GF8=0,"Feb ✓", "Feb") -> Feb ✓ | GG7: =IF(GG8=0,"Mar ✓", "Mar") -> Mar ✓ | GH7: =IF(GH8=0,"Apr ✓", "Apr") -> Apr ✓ | GI7: =IF(GI8=0,"May ✓", "May") -> May ✓ | GJ7: =IF(GJ8=0,"Jun ✓", "Jun") -> Jun ✓ | GK7: =IF(GK8=0,"Jul ✓", "Jul") -> Jul ✓ | GL7: =IF(GL8=0,"Aug ✓", "Aug") -> Aug ✓ | GM7: =IF(GM8=0,"Sep ✓", "Sep") -> Sep ✓ | GN7: =IF(GN8=0,"Oct ✓", "Oct") -> Oct ✓ | GO7: =IF(GO8=0,"Nov ✓", "Nov") -> Nov ✓ | GP7: =IF(GP8=0,"Dec ✓", "Dec") -> Dec ✓ | GQ7: =IF(GQ8=0,"Total ✓", "Total") -> Total ✓ | GS7: =IF(GS8=0,"Jan ✓", "Jan") -> Jan ✓ | GT7: =IF(GT8=0,"Feb ✓", "Feb") -> Feb ✓ | GU7: =IF(GU8=0,"Mar ✓", "Mar") -> Mar ✓ | GV7: =IF(GV8=0,"Apr ✓", "Apr") -> Apr ✓ | GW7: =IF(GW8=0,"May ✓", "May") -> May ✓ | GX7: =IF(GX8=0,"Jun ✓", "Jun") -> Jun ✓ | GY7: =IF(GY8=0,"Jul ✓", "Jul") -> Jul ✓ | GZ7: =IF(GZ8=0,"Aug ✓", "Aug") -> Aug ✓ | HA7: =IF(HA8=0,"Sep ✓", "Sep") -> Sep ✓ | HB7: =IF(HB8=0,"Oct ✓", "Oct") -> Oct ✓ | HC7: =IF(HC8=0,"Nov ✓", "Nov") -> Nov ✓ | HD7: =IF(HD8=0,"Dec ✓", "Dec") -> Dec ✓ | HE7: =IF(HE8=0,"Total ✓", "Total") -> Total ✓ | HG7: =IF(HG8=0,"Jan ✓", "Jan") -> Jan ✓ | HH7: =IF(HH8=0,"Feb ✓", "Feb") -> Feb ✓ | HI7: =IF(HI8=0,"Mar ✓", "Mar") -> Mar ✓ | HJ7: =IF(HJ8=0,"Apr ✓", "Apr") -> Apr ✓ | HK7: =IF(HK8=0,"May ✓", "May") -> May ✓ | HL7: =IF(HL8=0,"Jun ✓", "Jun") -> Jun ✓ | HM7: =IF(HM8=0,"Jul ✓", "Jul") -> Jul ✓ | HN7: =IF(HN8=0,"Aug ✓", "Aug") -> Aug ✓ | HO7: =IF(HO8=0,"Sep ✓", "Sep") -> Sep ✓ | HP7: =IF(HP8=0,"Oct ✓", "Oct") -> Oct ✓ | HQ7: =IF(HQ8=0,"Nov ✓", "Nov") -> Nov ✓ | HR7: =IF(HR8=0,"Dec ✓", "Dec") -> Dec ✓ | HS7: =IF(HS8=0,"Total ✓", "Total") -> Total ✓ | HU7: =IF(HU8=0,"Jan ✓", "Jan") -> Jan ✓ | HV7: =IF(HV8=0,"Feb ✓", "Feb") -> Feb ✓ | HW7: =IF(HW8=0,"Mar ✓", "Mar") -> Mar ✓ | HX7: =IF(HX8=0,"Apr ✓", "Apr") -> Apr ✓ | HY7: =IF(HY8=0,"May ✓", "May") -> May ✓ | HZ7: =IF(HZ8=0,"Jun ✓", "Jun") -> Jun ✓ | IA7: =IF(IA8=0,"Jul ✓", "Jul") -> Jul ✓ | IB7: =IF(IB8=0,"Aug ✓", "Aug") -> Aug ✓ | IC7: =IF(IC8=0,"Sep ✓", "Sep") -> Sep ✓ | ID7: =IF(ID8=0,"Oct ✓", "Oct") -> Oct ✓ | IE7: =IF(IE8=0,"Nov ✓", "Nov") -> Nov ✓ | IF7: =IF(IF8=0,"Dec ✓", "Dec") -> Dec ✓ | IG7: =IF(IG8=0,"Total ✓", "Total") -> Total ✓
C8: To be allocated: | E8: =E24-(E52+E66) -> 0 | F8: =F24-(F52+F66) -> 0 | G8: =G24-(G52+G66) -> 0 | H8: =H24-(H52+H66) -> 0 | I8: =I24-(I52+I66) -> 0 | J8: =J24-(J52+J66) -> 0 | K8: =K24-(K52+K66) -> 0 | L8: =L24-(L52+L66) -> 782.6 | ... Q8: =Q24-(Q52+Q66) -> 15415.6 | S8: =S24-(S52+S66) -> 3886.0967 | T8: =T24-(T52+T66) -> 3886.3467 | U8: =U24-(U52+U66) -> 3886.3467 | V8: =V24-(V52+V66) -> 3886.3467 | W8: =W24-(W52+W66) -> 3886.3467 | X8: =X24-(X52+X66) -> 3886.3467 | Y8: =Y24-(Y52+Y66) -> 3886.3467 | Z8: =Z24-(Z52+Z66) -> 3886.3467 | ... AE8: =AE24-(AE52+AE66) -> 46633.08 | AG8: =AG24-(AG52+AG66) -> 0 | AH8: =AH24-(AH52+AH66) -> 0 | AI8: =AI24-(AI52+AI66) -> 0 | AJ8: =AJ24-(AJ52+AJ66) -> 0 | AK8: =AK24-(AK52+AK66) -> 0 | AL8: =AL24-(AL52+AL66) -> 0 | AM8: =AM24-(AM52+AM66) -> 0 | AN8: =AN24-(AN52+AN66) -> 0 | ... AS8: =AS24-(AS52+AS66) -> 0 | AU8: =AU24-(AU52+AU66) -> 0 | AV8: =AV24-(AV52+AV66) -> 0 | AW8: =AW24-(AW52+AW66) -> 0 | AX8: =AX24-(AX52+AX66) -> 0 | AY8: =AY24-(AY52+AY66) -> 0 | AZ8: =AZ24-(AZ52+AZ66) -> 0 | BA8: =BA24-(BA52+BA66) -> 0 | BB8: =BB24-(BB52+BB66) -> 0 | ... BG8: =BG24-(BG52+BG66) -> 0 | BI8: =BI24-(BI52+BI66) -> 0 | BJ8: =BJ24-(BJ52+BJ66) -> 0 | BK8: =BK24-(BK52+BK66) -> 0 | BL8: =BL24-(BL52+BL66) -> 0 | BM8: =BM24-(BM52+BM66) -> 0 | BN8: =BN24-(BN52+BN66) -> 0 | BO8: =BO24-(BO52+BO66) -> 0 | BP8: =BP24-(BP52+BP66) -> 0 | ... BU8: =BU24-(BU52+BU66) -> 0 | BW8: =BW24-(BW52+BW66) -> 0 | BX8: =BX24-(BX52+BX66) -> 0 | BY8: =BY24-(BY52+BY66) -> 0 | BZ8: =BZ24-(BZ52+BZ66) -> 0 | CA8: =CA24-(CA52+CA66) -> 0 | CB8: =CB24-(CB52+CB66) -> 0 | CC8: =CC24-(CC52+CC66) -> 0 | CD8: =CD24-(CD52+CD66) -> 0 | ... CI8: =CI24-(CI52+CI66) -> 0 | CK8: =CK24-(CK52+CK66) -> 0 | CL8: =CL24-(CL52+CL66) -> 0 | CM8: =CM24-(CM52+CM66) -> 0 | CN8: =CN24-(CN52+CN66) -> 0 | CO8: =CO24-(CO52+CO66) -> 0 | CP8: =CP24-(CP52+CP66) -> 0 | CQ8: =CQ24-(CQ52+CQ66) -> 0 | CR8: =CR24-(CR52+CR66) -> 0 | ... CW8: =CW24-(CW52+CW66) -> 0 | CY8: =CY24-(CY52+CY66) -> 0 | CZ8: =CZ24-(CZ52+CZ66) -> 0 | DA8: =DA24-(DA52+DA66) -> 0 | DB8: =DB24-(DB52+DB66) -> 0 | DC8: =DC24-(DC52+DC66) -> 0 | DD8: =DD24-(DD52+DD66) -> 0 | DE8: =DE24-(DE52+DE66) -> 0 | DF8: =DF24-(DF52+DF66) -> 0 | ... DK8: =DK24-(DK52+DK66) -> 0 | DM8: =DM24-(DM52+DM66) -> 0 | DN8: =DN24-(DN52+DN66) -> 0 | DO8: =DO24-(DO52+DO66) -> 0 | DP8: =DP24-(DP52+DP66) -> 0 | DQ8: =DQ24-(DQ52+DQ66) -> 0 | DR8: =DR24-(DR52+DR66) -> 0 | DS8: =DS24-(DS52+DS66) -> 0 | DT8: =DT24-(DT52+DT66) -> 0 | ... DY8: =DY24-(DY52+DY66) -> 0 | EA8: =EA24-(EA52+EA66) -> 0 | EB8: =EB24-(EB52+EB66) -> 0 | EC8: =EC24-(EC52+EC66) -> 0 | ED8: =ED24-(ED52+ED66) -> 0 | EE8: =EE24-(EE52+EE66) -> 0 | EF8: =EF24-(EF52+EF66) -> 0 | EG8: =EG24-(EG52+EG66) -> 0 | EH8: =EH24-(EH52+EH66) -> 0 | ... EM8: =EM24-(EM52+EM66) -> 0 | EO8: =EO24-(EO52+EO66) -> 0 | EP8: =EP24-(EP52+EP66) -> 0 | EQ8: =EQ24-(EQ52+EQ66) -> 0 | ER8: =ER24-(ER52+ER66) -> 0 | ES8: =ES24-(ES52+ES66) -> 0 | ET8: =ET24-(ET52+ET66) -> 0 | EU8: =EU24-(EU52+EU66) -> 0 | EV8: =EV24-(EV52+EV66) -> 0 | ... FA8: =FA24-(FA52+FA66) -> 0 | FC8: =FC24-(FC52+FC66) -> 0 | FD8: =FD24-(FD52+FD66) -> 0 | FE8: =FE24-(FE52+FE66) -> 0 | FF8: =FF24-(FF52+FF66) -> 0 | FG8: =FG24-(FG52+FG66) -> 0 | FH8: =FH24-(FH52+FH66) -> 0 | FI8: =FI24-(FI52+FI66) -> 0 | FJ8: =FJ24-(FJ52+FJ66) -> 0 | ... FO8: =FO24-(FO52+FO66) -> 0 | FQ8: =FQ24-(FQ52+FQ66) -> 0 | FR8: =FR24-(FR52+FR66) -> 0 | FS8: =FS24-(FS52+FS66) -> 0 | FT8: =FT24-(FT52+FT66) -> 0 | FU8: =FU24-(FU52+FU66) -> 0 | FV8: =FV24-(FV52+FV66) -> 0 | FW8: =FW24-(FW52+FW66) -> 0 | FX8: =FX24-(FX52+FX66) -> 0 | ... GC8: =GC24-(GC52+GC66) -> 0 | GE8: =GE24-(GE52+GE66) -> 0 | GF8: =GF24-(GF52+GF66) -> 0 | GG8: =GG24-(GG52+GG66) -> 0 | GH8: =GH24-(GH52+GH66) -> 0 | GI8: =GI24-(GI52+GI66) -> 0 | GJ8: =GJ24-(GJ52+GJ66) -> 0 | GK8: =GK24-(GK52+GK66) -> 0 | GL8: =GL24-(GL52+GL66) -> 0 | ... GQ8: =GQ24-(GQ52+GQ66) -> 0 | GS8: =GS24-(GS52+GS66) -> 0 | GT8: =GT24-(GT52+GT66) -> 0 | GU8: =GU24-(GU52+GU66) -> 0 | GV8: =GV24-(GV52+GV66) -> 0 | GW8: =GW24-(GW52+GW66) -> 0 | GX8: =GX24-(GX52+GX66) -> 0 | GY8: =GY24-(GY52+GY66) -> 0 | GZ8: =GZ24-(GZ52+GZ66) -> 0 | ... HE8: =HE24-(HE52+HE66) -> 0 | HG8: =HG24-(HG52+HG66) -> 0 | HH8: =HH24-(HH52+HH66) -> 0 | HI8: =HI24-(HI52+HI66) -> 0 | HJ8: =HJ24-(HJ52+HJ66) -> 0 | HK8: =HK24-(HK52+HK66) -> 0 | HL8: =HL24-(HL52+HL66) -> 0 | HM8: =HM24-(HM52+HM66) -> 0 | HN8: =HN24-(HN52+HN66) -> 0 | ... HS8: =HS24-(HS52+HS66) -> 0 | HU8: =HU24-(HU52+HU66) -> 0 | HV8: =HV24-(HV52+HV66) -> 0 | HW8: =HW24-(HW52+HW66) -> 0 | HX8: =HX24-(HX52+HX66) -> 0 | HY8: =HY24-(HY52+HY66) -> 0 | HZ8: =HZ24-(HZ52+HZ66) -> 0 | IA8: =IA24-(IA52+IA66) -> 0 | IB8: =IB24-(IB52+IB66) -> 0 | ... IG8: =IG24-(IG52+IG66) -> 0
C9: % Diff | L9: =(L10-L8)/L8 -> 2.9063251 | M9: =(M10-M8)/M8 -> 0.24992392 | N9: =(N10-N8)/N8 -> 0.68699348 | O9: =(O10-O8)/O8 -> 0.73632899 | P9: =(P10-P8)/P8 -> 2.9041729 | Q9: =(Q10-Q8)/Q8 -> -0.22552479
C10: Reality | L10: {=SUMPRODUCT( (INDEX(Tracking[Year],0)=$E$6) * (INDEX(Tracking[Month],0)=MONTH(DATEVALUE(L7 & " 1"))) * (INDEX(Tracking[Amount],0)) * (INDEX(Tracking[Type],0)="Income") ) - SUMPRODUCT( (INDEX(Tracking[Year],0)=$E$6) * (INDEX(Tracking[Month],0)=MONTH(DATEVALUE(L7 & " 1"))) * (INDEX(Tracking[Amount],0)) * (INDEX(Tracking[Type],0)="Expenses") )} -> 3057.09 | M10: {=SUMPRODUCT( (INDEX(Tracking[Year],0)=$E$6) * (INDEX(Tracking[Month],0)=MONTH(DATEVALUE(M7 & " 1"))) * (INDEX(Tracking[Amount],0)) * (INDEX(Tracking[Type],0)="Income") ) - SUMPRODUCT( (INDEX(Tracking[Year],0)=$E$6) * (INDEX(Tracking[Month],0)=MONTH(DATEVALUE(M7 & " 1"))) * (INDEX(Tracking[Amount],0)) * (INDEX(Tracking[Type],0)="Expenses") )} -> 5092.69 | N10: {=SUMPRODUCT( (INDEX(Tracking[Year],0)=$E$6) * (INDEX(Tracking[Month],0)=MONTH(DATEVALUE(N7 & " 1"))) * (INDEX(Tracking[Amount],0)) * (INDEX(Tracking[Type],0)="Income") ) - SUMPRODUCT( (INDEX(Tracking[Year],0)=$E$6) * (INDEX(Tracking[Month],0)=MONTH(DATEVALUE(N7 & " 1"))) * (INDEX(Tracking[Amount],0)) * (INDEX(Tracking[Type],0)="Expenses") )} -> 2560.35 | O10: {=SUMPRODUCT( (INDEX(Tracking[Year],0)=$E$6) * (INDEX(Tracking[Month],0)=MONTH(DATEVALUE(O7 & " 1"))) * (INDEX(Tracking[Amount],0)) * (INDEX(Tracking[Type],0)="Income") )- SUMPRODUCT( (INDEX(Tracking[Type],0)=2025) * (INDEX(Tracking[Date],0)=MONTH(DATEVALUE(O7 & " 1"))) * (INDEX(Tracking[Balance],0)) * (INDEX(Tracking[Amount],0)="Expenses") )} -> 12529.35 | P10: {=SUMPRODUCT( (INDEX(Tracking[Year],0)=$E$6) * (INDEX(Tracking[Month],0)=MONTH(DATEVALUE(P7 & " 1"))) * (INDEX(Tracking[Amount],0)) * (INDEX(Tracking[Type],0)="Income") )- SUMPRODUCT( (INDEX(Tracking[Type],0)=2025) * (INDEX(Tracking[Date],0)=MONTH(DATEVALUE(P7 & " 1"))) * (INDEX(Tracking[Balance],0)) * (INDEX(Tracking[Amount],0)="Expenses") )} -> 9075.25 | Q10: 11939
C12: Income | E12: =DATE(E$6,1,1) -> 45658 | F12: =DATE(E$6,2,1) -> 45689 | G12: =DATE(E$6,3,1) -> 45717 | H12: =DATE(E$6,4,1) -> 45748 | I12: =DATE(E$6,5,1) -> 45778 | J12: =DATE(E$6,6,1) -> 45809 | K12: =DATE(E$6,7,1) -> 45839 | L12: =DATE(E$6,8,1) -> 45870 | M12: =DATE(E$6,9,1) -> 45901 | N12: =DATE(E$6,10,1) -> 45931 | O12: =DATE(E$6,11,1) -> 45962 | P12: =DATE(E$6,12,1) -> 45992 | Q12: =E$6 -> 2025 | S12: =DATE(S$6,1,1) -> 46023 | T12: =DATE(S$6,2,1) -> 46054 | U12: =DATE(S$6,3,1) -> 46082 | V12: =DATE(S$6,4,1) -> 46113 | W12: =DATE(S$6,5,1) -> 46143 | X12: =DATE(S$6,6,1) -> 46174 | Y12: =DATE(S$6,7,1) -> 46204 | Z12: =DATE(S$6,8,1) -> 46235 | AA12: =DATE(S$6,9,1) -> 46266 | AB12: =DATE(S$6,10,1) -> 46296 | AC12: =DATE(S$6,11,1) -> 46327 | AD12: =DATE(S$6,12,1) -> 46357 | AE12: =S$6 -> 2026 | AG12: =DATE(AG$6,1,1) -> 46388 | AH12: =DATE(AG$6,2,1) -> 46419 | AI12: =DATE(AG$6,3,1) -> 46447 | AJ12: =DATE(AG$6,4,1) -> 46478 | AK12: =DATE(AG$6,5,1) -> 46508 | AL12: =DATE(AG$6,6,1) -> 46539 | AM12: =DATE(AG$6,7,1) -> 46569 | AN12: =DATE(AG$6,8,1) -> 46600 | AO12: =DATE(AG$6,9,1) -> 46631 | AP12: =DATE(AG$6,10,1) -> 46661 | AQ12: =DATE(AG$6,11,1) -> 46692 | AR12: =DATE(AG$6,12,1) -> 46722 | AS12: =AG$6 -> 2027 | AU12: =DATE(AU$6,1,1) -> 46753 | AV12: =DATE(AU$6,2,1) -> 46784 | AW12: =DATE(AU$6,3,1) -> 46813 | AX12: =DATE(AU$6,4,1) -> 46844 | AY12: =DATE(AU$6,5,1) -> 46874 | AZ12: =DATE(AU$6,6,1) -> 46905 | BA12: =DATE(AU$6,7,1) -> 46935 | BB12: =DATE(AU$6,8,1) -> 46966 | BC12: =DATE(AU$6,9,1) -> 46997 | BD12: =DATE(AU$6,10,1) -> 47027 | BE12: =DATE(AU$6,11,1) -> 47058 | BF12: =DATE(AU$6,12,1) -> 47088 | BG12: =AU$6 -> 2028 | BI12: =DATE(BI$6,1,1) -> 47119 | BJ12: =DATE(BI$6,2,1) -> 47150 | BK12: =DATE(BI$6,3,1) -> 47178 | BL12: =DATE(BI$6,4,1) -> 47209 | BM12: =DATE(BI$6,5,1) -> 47239 | BN12: =DATE(BI$6,6,1) -> 47270 | BO12: =DATE(BI$6,7,1) -> 47300 | BP12: =DATE(BI$6,8,1) -> 47331 | BQ12: =DATE(BI$6,9,1) -> 47362 | BR12: =DATE(BI$6,10,1) -> 47392 | BS12: =DATE(BI$6,11,1) -> 47423 | BT12: =DATE(BI$6,12,1) -> 47453 | BU12: =BI$6 -> 2029 | BW12: =DATE(BW$6,1,1) -> 47484 | BX12: =DATE(BW$6,2,1) -> 47515 | BY12: =DATE(BW$6,3,1) -> 47543 | BZ12: =DATE(BW$6,4,1) -> 47574 | CA12: =DATE(BW$6,5,1) -> 47604 | CB12: =DATE(BW$6,6,1) -> 47635 | CC12: =DATE(BW$6,7,1) -> 47665 | CD12: =DATE(BW$6,8,1) -> 47696 | CE12: =DATE(BW$6,9,1) -> 47727 | CF12: =DATE(BW$6,10,1) -> 47757 | CG12: =DATE(BW$6,11,1) -> 47788 | CH12: =DATE(BW$6,12,1) -> 47818 | CI12: =BW$6 -> 2030 | CK12: =DATE(CK$6,1,1) -> 47849 | CL12: =DATE(CK$6,2,1) -> 47880 | CM12: =DATE(CK$6,3,1) -> 47908 | CN12: =DATE(CK$6,4,1) -> 47939 | CO12: =DATE(CK$6,5,1) -> 47969 | CP12: =DATE(CK$6,6,1) -> 48000 | CQ12: =DATE(CK$6,7,1) -> 48030 | CR12: =DATE(CK$6,8,1) -> 48061 | CS12: =DATE(CK$6,9,1) -> 48092 | CT12: =DATE(CK$6,10,1) -> 48122 | CU12: =DATE(CK$6,11,1) -> 48153 | CV12: =DATE(CK$6,12,1) -> 48183 | CW12: =CK$6 -> 2031 | CY12: =DATE(CY$6,1,1) -> 48214 | CZ12: =DATE(CY$6,2,1) -> 48245 | DA12: =DATE(CY$6,3,1) -> 48274 | DB12: =DATE(CY$6,4,1) -> 48305 | DC12: =DATE(CY$6,5,1) -> 48335 | DD12: =DATE(CY$6,6,1) -> 48366 | DE12: =DATE(CY$6,7,1) -> 48396 | DF12: =DATE(CY$6,8,1) -> 48427 | DG12: =DATE(CY$6,9,1) -> 48458 | DH12: =DATE(CY$6,10,1) -> 48488 | DI12: =DATE(CY$6,11,1) -> 48519 | DJ12: =DATE(CY$6,12,1) -> 48549 | DK12: =CY$6 -> 2032 | DM12: =DATE(DM$6,1,1) -> 48580 | DN12: =DATE(DM$6,2,1) -> 48611 | DO12: =DATE(DM$6,3,1) -> 48639 | DP12: =DATE(DM$6,4,1) -> 48670 | DQ12: =DATE(DM$6,5,1) -> 48700 | DR12: =DATE(DM$6,6,1) -> 48731 | DS12: =DATE(DM$6,7,1) -> 48761 | DT12: =DATE(DM$6,8,1) -> 48792 | DU12: =DATE(DM$6,9,1) -> 48823 | DV12: =DATE(DM$6,10,1) -> 48853 | DW12: =DATE(DM$6,11,1) -> 48884 | DX12: =DATE(DM$6,12,1) -> 48914 | DY12: =DM$6 -> 2033 | EA12: =DATE(EA$6,1,1) -> 48945 | EB12: =DATE(EA$6,2,1) -> 48976 | EC12: =DATE(EA$6,3,1) -> 49004 | ED12: =DATE(EA$6,4,1) -> 49035 | EE12: =DATE(EA$6,5,1) -> 49065 | EF12: =DATE(EA$6,6,1) -> 49096 | EG12: =DATE(EA$6,7,1) -> 49126 | EH12: =DATE(EA$6,8,1) -> 49157 | EI12: =DATE(EA$6,9,1) -> 49188 | EJ12: =DATE(EA$6,10,1) -> 49218 | EK12: =DATE(EA$6,11,1) -> 49249 | EL12: =DATE(EA$6,12,1) -> 49279 | EM12: =EA$6 -> 2034 | EO12: =DATE(EO$6,1,1) -> 49310 | EP12: =DATE(EO$6,2,1) -> 49341 | EQ12: =DATE(EO$6,3,1) -> 49369 | ER12: =DATE(EO$6,4,1) -> 49400 | ES12: =DATE(EO$6,5,1) -> 49430 | ET12: =DATE(EO$6,6,1) -> 49461 | EU12: =DATE(EO$6,7,1) -> 49491 | EV12: =DATE(EO$6,8,1) -> 49522 | EW12: =DATE(EO$6,9,1) -> 49553 | EX12: =DATE(EO$6,10,1) -> 49583 | EY12: =DATE(EO$6,11,1) -> 49614 | EZ12: =DATE(EO$6,12,1) -> 49644 | FA12: =EO$6 -> 2035 | FC12: =DATE(FC$6,1,1) -> 49675 | FD12: =DATE(FC$6,2,1) -> 49706 | FE12: =DATE(FC$6,3,1) -> 49735 | FF12: =DATE(FC$6,4,1) -> 49766 | FG12: =DATE(FC$6,5,1) -> 49796 | FH12: =DATE(FC$6,6,1) -> 49827 | FI12: =DATE(FC$6,7,1) -> 49857 | FJ12: =DATE(FC$6,8,1) -> 49888 | FK12: =DATE(FC$6,9,1) -> 49919 | FL12: =DATE(FC$6,10,1) -> 49949 | FM12: =DATE(FC$6,11,1) -> 49980 | FN12: =DATE(FC$6,12,1) -> 50010 | FO12: =FC$6 -> 2036 | FQ12: =DATE(FQ$6,1,1) -> 50041 | FR12: =DATE(FQ$6,2,1) -> 50072 | FS12: =DATE(FQ$6,3,1) -> 50100 | FT12: =DATE(FQ$6,4,1) -> 50131 | FU12: =DATE(FQ$6,5,1) -> 50161 | FV12: =DATE(FQ$6,6,1) -> 50192 | FW12: =DATE(FQ$6,7,1) -> 50222 | FX12: =DATE(FQ$6,8,1) -> 50253 | FY12: =DATE(FQ$6,9,1) -> 50284 | FZ12: =DATE(FQ$6,10,1) -> 50314 | GA12: =DATE(FQ$6,11,1) -> 50345 | GB12: =DATE(FQ$6,12,1) -> 50375 | GC12: =FQ$6 -> 2037 | GE12: =DATE(GE$6,1,1) -> 50406 | GF12: =DATE(GE$6,2,1) -> 50437 | GG12: =DATE(GE$6,3,1) -> 50465 | GH12: =DATE(GE$6,4,1) -> 50496 | GI12: =DATE(GE$6,5,1) -> 50526 | GJ12: =DATE(GE$6,6,1) -> 50557 | GK12: =DATE(GE$6,7,1) -> 50587 | GL12: =DATE(GE$6,8,1) -> 50618 | GM12: =DATE(GE$6,9,1) -> 50649 | GN12: =DATE(GE$6,10,1) -> 50679 | GO12: =DATE(GE$6,11,1) -> 50710 | GP12: =DATE(GE$6,12,1) -> 50740 | GQ12: =GE$6 -> 2038 | GS12: =DATE(GS$6,1,1) -> 50771 | GT12: =DATE(GS$6,2,1) -> 50802 | GU12: =DATE(GS$6,3,1) -> 50830 | GV12: =DATE(GS$6,4,1) -> 50861 | GW12: =DATE(GS$6,5,1) -> 50891 | GX12: =DATE(GS$6,6,1) -> 50922 | GY12: =DATE(GS$6,7,1) -> 50952 | GZ12: =DATE(GS$6,8,1) -> 50983 | HA12: =DATE(GS$6,9,1) -> 51014 | HB12: =DATE(GS$6,10,1) -> 51044 | HC12: =DATE(GS$6,11,1) -> 51075 | HD12: =DATE(GS$6,12,1) -> 51105 | HE12: =GS$6 -> 2039 | HG12: =DATE(HG$6,1,1) -> 51136 | HH12: =DATE(HG$6,2,1) -> 51167 | HI12: =DATE(HG$6,3,1) -> 51196 | HJ12: =DATE(HG$6,4,1) -> 51227 | HK12: =DATE(HG$6,5,1) -> 51257 | HL12: =DATE(HG$6,6,1) -> 51288 | HM12: =DATE(HG$6,7,1) -> 51318 | HN12: =DATE(HG$6,8,1) -> 51349 | HO12: =DATE(HG$6,9,1) -> 51380 | HP12: =DATE(HG$6,10,1) -> 51410 | HQ12: =DATE(HG$6,11,1) -> 51441 | HR12: =DATE(HG$6,12,1) -> 51471 | HS12: =HG$6 -> 2040 | HU12: =DATE(HU$6,1,1) -> 51502 | HV12: =DATE(HU$6,2,1) -> 51533 | HW12: =DATE(HU$6,3,1) -> 51561 | HX12: =DATE(HU$6,4,1) -> 51592 | HY12: =DATE(HU$6,5,1) -> 51622 | HZ12: =DATE(HU$6,6,1) -> 51653 | IA12: =DATE(HU$6,7,1) -> 51683 | IB12: =DATE(HU$6,8,1) -> 51714 | IC12: =DATE(HU$6,9,1) -> 51745 | ID12: =DATE(HU$6,10,1) -> 51775 | IE12: =DATE(HU$6,11,1) -> 51806 | IF12: =DATE(HU$6,12,1) -> 51836 | IG12: =HU$6 -> 2041
C13: Employment | L13: {=SUMPRODUCT((Tracking[Type]="Income")*(Tracking[Category]=Income[[#This Row],[Income]])*(MONTH(Tracking[Date])=8)*(Tracking[Amount])*1)} -> 3587.1 | M13: {=SUMPRODUCT((Tracking[Type]="Income")*(Tracking[Category]=Income[[#This Row],[Income]])*(MONTH(Tracking[Date])=9)*(Tracking[Amount])*1)} -> 8204.85 | N13: {=SUMPRODUCT((Previsions[Type]="Income")*(Previsions[Cat]="Employment")*(Previsions[Final Budget])*1)} -> 8204.85 | O13: {=SUMPRODUCT((Previsions[Type]="Income")*(Previsions[Cat]="Employment")*(Previsions[Final Budget])*1)} -> 8204.85 | P13: {=SUMPRODUCT((Previsions[Type]="Income")*(Previsions[Cat]="Employment")*(Previsions[Final Budget])*1)} -> 8204.85 | Q13: =SUM(E13:P13) -> 36406.5 | S13: 8205 | T13: 8205 | U13: 8205 | V13: 8205 | W13: 8205 | X13: 8205 | Y13: 8205 | Z13: 8205 | AA13: 8205 | AB13: 8205 | AC13: 8205 | AD13: 8205 | AE13: =SUM(S13:AD13) -> 98460 | AS13: =SUM(AG13:AR13) -> 0 | BG13: =SUM(AU13:BF13) -> 0
C14: Grant Payment | O14: {=SUMPRODUCT((Tracking[Type]="Income")*(Tracking[Category]=Income[[#This Row],[Income]])*(MONTH(Tracking[Date])=11)*(Tracking[Amount])*1)} -> 4000 | Q14: 4000
C15: Side Hustle | L15: {=SUMPRODUCT((Tracking[Type]="Income")*(Tracking[Category]=Income[[#This Row],[Income]])*(MONTH(Tracking[Date])=8)*(Tracking[Amount])*1)} -> 4313.3 | M15: {=SUMPRODUCT((Tracking[Type]="Income")*(Tracking[Category]=Income[[#This Row],[Income]])*(MONTH(Tracking[Date])=9)*(Tracking[Amount])*1)} -> 1699.9 | N15: {=SUMPRODUCT((Tracking[Type]="Income")*(Tracking[Category]=Income[[#This Row],[Income]])*(MONTH(Tracking[Date])=10)*(Tracking[Amount])*1)} -> 0 | O15: {=SUMPRODUCT((Tracking[Type]="Income")*(Tracking[Category]=Income[[#This Row],[Income]])*(MONTH(Tracking[Date])=11)*(Tracking[Amount])*1)} -> 0 | P15: {=SUMPRODUCT((Tracking[Type]="Income")*(Tracking[Category]=Income[[#This Row],[Income]])*(MONTH(Tracking[Date])=12)*(Tracking[Amount])*1)} -> 0 | Q15: =SUM(E15:P15) -> 6013.2 | AE15: =SUM(S15:AD15) -> 0 | AS15: =SUM(AG15:AR15) -> 0 | BG15: =SUM(AU15:BF15) -> 0
C16: Extras / Twint Chargeback | L16: {=SUMPRODUCT((Tracking[Type]="Income")*(Tracking[Category]=Income[[#This Row],[Income]])*(MONTH(Tracking[Date])=8)*(Tracking[Amount])*1)} -> 195.55 | M16: {=SUMPRODUCT((Tracking[Type]="Income")*(Tracking[Category]=Income[[#This Row],[Income]])*(MONTH(Tracking[Date])=9)*(Tracking[Amount])*1)} -> 38 | N16: {=SUMPRODUCT((Tracking[Type]="Income")*(Tracking[Category]=Income[[#This Row],[Income]])*(MONTH(Tracking[Date])=10)*(Tracking[Amount])*1)} -> 71.2 | O16: {=SUMPRODUCT((Tracking[Type]="Income")*(Tracking[Category]=Income[[#This Row],[Income]])*(MONTH(Tracking[Date])=11)*(Tracking[Amount])*1)} -> 324.5 | P16: {=SUMPRODUCT((Tracking[Type]="Income")*(Tracking[Category]=Income[[#This Row],[Income]])*(MONTH(Tracking[Date])=12)*(Tracking[Amount])*1)} -> 531 | Q16: =SUM(E16:P16) -> 1160.25 | AE16: =SUM(S16:AD16) -> 0 | AS16: =SUM(AG16:AR16) -> 0 | BG16: =SUM(AU16:BF16) -> 0 | BU16: =SUM(BI16:BT16) -> 0 | CI16: =SUM(BW16:CH16) -> 0 | CW16: =SUM(CK16:CV16) -> 0 | DK16: =SUM(CY16:DJ16) -> 0 | DY16: =SUM(DM16:DX16) -> 0 | EM16: =SUM(EA16:EL16) -> 0 | FA16: =SUM(EO16:EZ16) -> 0 | FO16: =SUM(FC16:FN16) -> 0 | GC16: =SUM(FQ16:GB16) -> 0 | GQ16: =SUM(GE16:GP16) -> 0 | HE16: =SUM(GS16:HD16) -> 0 | HS16: =SUM(HG16:HR16) -> 0 | IG16: =SUM(HU16:IF16) -> 0
C17: Enter income Category…
C18: Enter income Category…
C19: Enter income Category… | Q19: =SUM(E19:P19) -> 0 | AE19: =SUM(S19:AD19) -> 0 | AS19: =SUM(AG19:AR19) -> 0 | BG19: =SUM(AU19:BF19) -> 0 | BU19: =SUM(BI19:BT19) -> 0 | CI19: =SUM(BW19:CH19) -> 0 | CW19: =SUM(CK19:CV19) -> 0 | DK19: =SUM(CY19:DJ19) -> 0 | DY19: =SUM(DM19:DX19) -> 0 | EM19: =SUM(EA19:EL19) -> 0 | FA19: =SUM(EO19:EZ19) -> 0 | FO19: =SUM(FC19:FN19) -> 0 | GC19: =SUM(FQ19:GB19) -> 0 | GQ19: =SUM(GE19:GP19) -> 0 | HE19: =SUM(GS19:HD19) -> 0 | HS19: =SUM(HG19:HR19) -> 0 | IG19: =SUM(HU19:IF19) -> 0
C20: Enter income Category… | Q20: =SUM(E20:P20) -> 0 | AE20: =SUM(S20:AD20) -> 0 | AS20: =SUM(AG20:AR20) -> 0 | BG20: =SUM(AU20:BF20) -> 0 | BU20: =SUM(BI20:BT20) -> 0 | CI20: =SUM(BW20:CH20) -> 0 | CW20: =SUM(CK20:CV20) -> 0 | DK20: =SUM(CY20:DJ20) -> 0 | DY20: =SUM(DM20:DX20) -> 0 | EM20: =SUM(EA20:EL20) -> 0 | FA20: =SUM(EO20:EZ20) -> 0 | FO20: =SUM(FC20:FN20) -> 0 | GC20: =SUM(FQ20:GB20) -> 0 | GQ20: =SUM(GE20:GP20) -> 0 | HE20: =SUM(GS20:HD20) -> 0 | HS20: =SUM(HG20:HR20) -> 0 | IG20: =SUM(HU20:IF20) -> 0
C21: Enter income Category… | Q21: =SUM(E21:P21) -> 0 | AE21: =SUM(S21:AD21) -> 0 | AS21: =SUM(AG21:AR21) -> 0 | BG21: =SUM(AU21:BF21) -> 0 | BU21: =SUM(BI21:BT21) -> 0 | CI21: =SUM(BW21:CH21) -> 0 | CW21: =SUM(CK21:CV21) -> 0 | DK21: =SUM(CY21:DJ21) -> 0 | DY21: =SUM(DM21:DX21) -> 0 | EM21: =SUM(EA21:EL21) -> 0 | FA21: =SUM(EO21:EZ21) -> 0 | FO21: =SUM(FC21:FN21) -> 0 | GC21: =SUM(FQ21:GB21) -> 0 | GQ21: =SUM(GE21:GP21) -> 0 | HE21: =SUM(GS21:HD21) -> 0 | HS21: =SUM(HG21:HR21) -> 0 | IG21: =SUM(HU21:IF21) -> 0
C22: Enter income Category… | Q22: =SUM(E22:P22) -> 0 | AE22: =SUM(S22:AD22) -> 0 | AS22: =SUM(AG22:AR22) -> 0 | BG22: =SUM(AU22:BF22) -> 0 | BU22: =SUM(BI22:BT22) -> 0 | CI22: =SUM(BW22:CH22) -> 0 | CW22: =SUM(CK22:CV22) -> 0 | DK22: =SUM(CY22:DJ22) -> 0 | DY22: =SUM(DM22:DX22) -> 0 | EM22: =SUM(EA22:EL22) -> 0 | FA22: =SUM(EO22:EZ22) -> 0 | FO22: =SUM(FC22:FN22) -> 0 | GC22: =SUM(FQ22:GB22) -> 0 | GQ22: =SUM(GE22:GP22) -> 0 | HE22: =SUM(GS22:HD22) -> 0 | HS22: =SUM(HG22:HR22) -> 0 | IG22: =SUM(HU22:IF22) -> 0
C23: Enter income Category… | Q23: =SUM(E23:P23) -> 0 | AE23: =SUM(S23:AD23) -> 0 | AS23: =SUM(AG23:AR23) -> 0 | BG23: =SUM(AU23:BF23) -> 0 | BU23: =SUM(BI23:BT23) -> 0 | CI23: =SUM(BW23:CH23) -> 0 | CW23: =SUM(CK23:CV23) -> 0 | DK23: =SUM(CY23:DJ23) -> 0 | DY23: =SUM(DM23:DX23) -> 0 | EM23: =SUM(EA23:EL23) -> 0 | FA23: =SUM(EO23:EZ23) -> 0 | FO23: =SUM(FC23:FN23) -> 0 | GC23: =SUM(FQ23:GB23) -> 0 | GQ23: =SUM(GE23:GP23) -> 0 | HE23: =SUM(GS23:HD23) -> 0 | HS23: =SUM(HG23:HR23) -> 0 | IG23: =SUM(HU23:IF23) -> 0
C24: Total | E24: {=SUM(INDIRECT(ADDRESS(income_min_row, COLUMN()) & ":" & ADDRESS(income_max_row, COLUMN())))} -> 0 | F24: {=SUM(INDIRECT(ADDRESS(income_min_row, COLUMN()) & ":" & ADDRESS(income_max_row, COLUMN())))} -> 0 | G24: {=SUM(INDIRECT(ADDRESS(income_min_row, COLUMN()) & ":" & ADDRESS(income_max_row, COLUMN())))} -> 0 | H24: {=SUM(INDIRECT(ADDRESS(income_min_row, COLUMN()) & ":" & ADDRESS(income_max_row, COLUMN())))} -> 0 | I24: {=SUM(INDIRECT(ADDRESS(income_min_row, COLUMN()) & ":" & ADDRESS(income_max_row, COLUMN())))} -> 0 | J24: {=SUM(INDIRECT(ADDRESS(income_min_row, COLUMN()) & ":" & ADDRESS(income_max_row, COLUMN())))} -> 0 | K24: {=SUM(INDIRECT(ADDRESS(income_min_row, COLUMN()) & ":" & ADDRESS(income_max_row, COLUMN())))} -> 0 | L24: {=SUM(INDIRECT(ADDRESS(income_min_row, COLUMN()) & ":" & ADDRESS(income_max_row, COLUMN())))} -> 8095.95 | ... Q24: {=SUM(INDIRECT(ADDRESS(income_min_row, COLUMN()) & ":" & ADDRESS(income_max_row, COLUMN())))} -> 47579.95 | S24: {=SUM(INDIRECT(ADDRESS(income_min_row, COLUMN()) & ":" & ADDRESS(income_max_row, COLUMN())))} -> 8205 | T24: {=SUM(INDIRECT(ADDRESS(income_min_row, COLUMN()) & ":" & ADDRESS(income_max_row, COLUMN())))} -> 8205 | U24: {=SUM(INDIRECT(ADDRESS(income_min_row, COLUMN()) & ":" & ADDRESS(income_max_row, COLUMN())))} -> 8205 | V24: {=SUM(INDIRECT(ADDRESS(income_min_row, COLUMN()) & ":" & ADDRESS(income_max_row, COLUMN())))} -> 8205 | W24: {=SUM(INDIRECT(ADDRESS(income_min_row, COLUMN()) & ":" & ADDRESS(income_max_row, COLUMN())))} -> 8205 | X24: {=SUM(INDIRECT(ADDRESS(income_min_row, COLUMN()) & ":" & ADDRESS(income_max_row, COLUMN())))} -> 8205 | Y24: {=SUM(INDIRECT(ADDRESS(income_min_row, COLUMN()) & ":" & ADDRESS(income_max_row, COLUMN())))} -> 8205 | Z24: {=SUM(INDIRECT(ADDRESS(income_min_row, COLUMN()) & ":" & ADDRESS(income_max_row, COLUMN())))} -> 8205 | ... AE24: {=SUM(INDIRECT(ADDRESS(income_min_row, COLUMN()) & ":" & ADDRESS(income_max_row, COLUMN())))} -> 98460 | AG24: {=SUM(INDIRECT(ADDRESS(income_min_row, COLUMN()) & ":" & ADDRESS(income_max_row, COLUMN())))} -> 0 | AH24: {=SUM(INDIRECT(ADDRESS(income_min_row, COLUMN()) & ":" & ADDRESS(income_max_row, COLUMN())))} -> 0 | AI24: {=SUM(INDIRECT(ADDRESS(income_min_row, COLUMN()) & ":" & ADDRESS(income_max_row, COLUMN())))} -> 0 | AJ24: {=SUM(INDIRECT(ADDRESS(income_min_row, COLUMN()) & ":" & ADDRESS(income_max_row, COLUMN())))} -> 0 | AK24: {=SUM(INDIRECT(ADDRESS(income_min_row, COLUMN()) & ":" & ADDRESS(income_max_row, COLUMN())))} -> 0 | AL24: {=SUM(INDIRECT(ADDRESS(income_min_row, COLUMN()) & ":" & ADDRESS(income_max_row, COLUMN())))} -> 0 | AM24: {=SUM(INDIRECT(ADDRESS(income_min_row, COLUMN()) & ":" & ADDRESS(income_max_row, COLUMN())))} -> 0 | AN24: {=SUM(INDIRECT(ADDRESS(income_min_row, COLUMN()) & ":" & ADDRESS(income_max_row, COLUMN())))} -> 0 | ... AS24: {=SUM(INDIRECT(ADDRESS(income_min_row, COLUMN()) & ":" & ADDRESS(income_max_row, COLUMN())))} -> 0 | AU24: {=SUM(INDIRECT(ADDRESS(income_min_row, COLUMN()) & ":" & ADDRESS(income_max_row, COLUMN())))} -> 0 | AV24: {=SUM(INDIRECT(ADDRESS(income_min_row, COLUMN()) & ":" & ADDRESS(income_max_row, COLUMN())))} -> 0 | AW24: {=SUM(INDIRECT(ADDRESS(income_min_row, COLUMN()) & ":" & ADDRESS(income_max_row, COLUMN())))} -> 0 | AX24: {=SUM(INDIRECT(ADDRESS(income_min_row, COLUMN()) & ":" & ADDRESS(income_max_row, COLUMN())))} -> 0 | AY24: {=SUM(INDIRECT(ADDRESS(income_min_row, COLUMN()) & ":" & ADDRESS(income_max_row, COLUMN())))} -> 0 | AZ24: {=SUM(INDIRECT(ADDRESS(income_min_row, COLUMN()) & ":" & ADDRESS(income_max_row, COLUMN())))} -> 0 | BA24: {=SUM(INDIRECT(ADDRESS(income_min_row, COLUMN()) & ":" & ADDRESS(income_max_row, COLUMN())))} -> 0 | BB24: {=SUM(INDIRECT(ADDRESS(income_min_row, COLUMN()) & ":" & ADDRESS(income_max_row, COLUMN())))} -> 0 | ... BG24: {=SUM(INDIRECT(ADDRESS(income_min_row, COLUMN()) & ":" & ADDRESS(income_max_row, COLUMN())))} -> 0 | BI24: {=SUM(INDIRECT(ADDRESS(income_min_row, COLUMN()) & ":" & ADDRESS(income_max_row, COLUMN())))} -> 0 | BJ24: {=SUM(INDIRECT(ADDRESS(income_min_row, COLUMN()) & ":" & ADDRESS(income_max_row, COLUMN())))} -> 0 | BK24: {=SUM(INDIRECT(ADDRESS(income_min_row, COLUMN()) & ":" & ADDRESS(income_max_row, COLUMN())))} -> 0 | BL24: {=SUM(INDIRECT(ADDRESS(income_min_row, COLUMN()) & ":" & ADDRESS(income_max_row, COLUMN())))} -> 0 | BM24: {=SUM(INDIRECT(ADDRESS(income_min_row, COLUMN()) & ":" & ADDRESS(income_max_row, COLUMN())))} -> 0 | BN24: {=SUM(INDIRECT(ADDRESS(income_min_row, COLUMN()) & ":" & ADDRESS(income_max_row, COLUMN())))} -> 0 | BO24: {=SUM(INDIRECT(ADDRESS(income_min_row, COLUMN()) & ":" & ADDRESS(income_max_row, COLUMN())))} -> 0 | BP24: {=SUM(INDIRECT(ADDRESS(income_min_row, COLUMN()) & ":" & ADDRESS(income_max_row, COLUMN())))} -> 0 | ... BU24: {=SUM(INDIRECT(ADDRESS(income_min_row, COLUMN()) & ":" & ADDRESS(income_max_row, COLUMN())))} -> 0 | BW24: {=SUM(INDIRECT(ADDRESS(income_min_row, COLUMN()) & ":" & ADDRESS(income_max_row, COLUMN())))} -> 0 | BX24: {=SUM(INDIRECT(ADDRESS(income_min_row, COLUMN()) & ":" & ADDRESS(income_max_row, COLUMN())))} -> 0 | BY24: {=SUM(INDIRECT(ADDRESS(income_min_row, COLUMN()) & ":" & ADDRESS(income_max_row, COLUMN())))} -> 0 | BZ24: {=SUM(INDIRECT(ADDRESS(income_min_row, COLUMN()) & ":" & ADDRESS(income_max_row, COLUMN())))} -> 0 | CA24: {=SUM(INDIRECT(ADDRESS(income_min_row, COLUMN()) & ":" & ADDRESS(income_max_row, COLUMN())))} -> 0 | CB24: {=SUM(INDIRECT(ADDRESS(income_min_row, COLUMN()) & ":" & ADDRESS(income_max_row, COLUMN())))} -> 0 | CC24: {=SUM(INDIRECT(ADDRESS(income_min_row, COLUMN()) & ":" & ADDRESS(income_max_row, COLUMN())))} -> 0 | CD24: {=SUM(INDIRECT(ADDRESS(income_min_row, COLUMN()) & ":" & ADDRESS(income_max_row, COLUMN())))} -> 0 | ... CI24: {=SUM(INDIRECT(ADDRESS(income_min_row, COLUMN()) & ":" & ADDRESS(income_max_row, COLUMN())))} -> 0 | CK24: {=SUM(INDIRECT(ADDRESS(income_min_row, COLUMN()) & ":" & ADDRESS(income_max_row, COLUMN())))} -> 0 | CL24: {=SUM(INDIRECT(ADDRESS(income_min_row, COLUMN()) & ":" & ADDRESS(income_max_row, COLUMN())))} -> 0 | CM24: {=SUM(INDIRECT(ADDRESS(income_min_row, COLUMN()) & ":" & ADDRESS(income_max_row, COLUMN())))} -> 0 | CN24: {=SUM(INDIRECT(ADDRESS(income_min_row, COLUMN()) & ":" & ADDRESS(income_max_row, COLUMN())))} -> 0 | CO24: {=SUM(INDIRECT(ADDRESS(income_min_row, COLUMN()) & ":" & ADDRESS(income_max_row, COLUMN())))} -> 0 | CP24: {=SUM(INDIRECT(ADDRESS(income_min_row, COLUMN()) & ":" & ADDRESS(income_max_row, COLUMN())))} -> 0 | CQ24: {=SUM(INDIRECT(ADDRESS(income_min_row, COLUMN()) & ":" & ADDRESS(income_max_row, COLUMN())))} -> 0 | CR24: {=SUM(INDIRECT(ADDRESS(income_min_row, COLUMN()) & ":" & ADDRESS(income_max_row, COLUMN())))} -> 0 | ... CW24: {=SUM(INDIRECT(ADDRESS(income_min_row, COLUMN()) & ":" & ADDRESS(income_max_row, COLUMN())))} -> 0 | CY24: {=SUM(INDIRECT(ADDRESS(income_min_row, COLUMN()) & ":" & ADDRESS(income_max_row, COLUMN())))} -> 0 | CZ24: {=SUM(INDIRECT(ADDRESS(income_min_row, COLUMN()) & ":" & ADDRESS(income_max_row, COLUMN())))} -> 0 | DA24: {=SUM(INDIRECT(ADDRESS(income_min_row, COLUMN()) & ":" & ADDRESS(income_max_row, COLUMN())))} -> 0 | DB24: {=SUM(INDIRECT(ADDRESS(income_min_row, COLUMN()) & ":" & ADDRESS(income_max_row, COLUMN())))} -> 0 | DC24: {=SUM(INDIRECT(ADDRESS(income_min_row, COLUMN()) & ":" & ADDRESS(income_max_row, COLUMN())))} -> 0 | DD24: {=SUM(INDIRECT(ADDRESS(income_min_row, COLUMN()) & ":" & ADDRESS(income_max_row, COLUMN())))} -> 0 | DE24: {=SUM(INDIRECT(ADDRESS(income_min_row, COLUMN()) & ":" & ADDRESS(income_max_row, COLUMN())))} -> 0 | DF24: {=SUM(INDIRECT(ADDRESS(income_min_row, COLUMN()) & ":" & ADDRESS(income_max_row, COLUMN())))} -> 0 | ... DK24: {=SUM(INDIRECT(ADDRESS(income_min_row, COLUMN()) & ":" & ADDRESS(income_max_row, COLUMN())))} -> 0 | DM24: {=SUM(INDIRECT(ADDRESS(income_min_row, COLUMN()) & ":" & ADDRESS(income_max_row, COLUMN())))} -> 0 | DN24: {=SUM(INDIRECT(ADDRESS(income_min_row, COLUMN()) & ":" & ADDRESS(income_max_row, COLUMN())))} -> 0 | DO24: {=SUM(INDIRECT(ADDRESS(income_min_row, COLUMN()) & ":" & ADDRESS(income_max_row, COLUMN())))} -> 0 | DP24: {=SUM(INDIRECT(ADDRESS(income_min_row, COLUMN()) & ":" & ADDRESS(income_max_row, COLUMN())))} -> 0 | DQ24: {=SUM(INDIRECT(ADDRESS(income_min_row, COLUMN()) & ":" & ADDRESS(income_max_row, COLUMN())))} -> 0 | DR24: {=SUM(INDIRECT(ADDRESS(income_min_row, COLUMN()) & ":" & ADDRESS(income_max_row, COLUMN())))} -> 0 | DS24: {=SUM(INDIRECT(ADDRESS(income_min_row, COLUMN()) & ":" & ADDRESS(income_max_row, COLUMN())))} -> 0 | DT24: {=SUM(INDIRECT(ADDRESS(income_min_row, COLUMN()) & ":" & ADDRESS(income_max_row, COLUMN())))} -> 0 | ... DY24: {=SUM(INDIRECT(ADDRESS(income_min_row, COLUMN()) & ":" & ADDRESS(income_max_row, COLUMN())))} -> 0 | EA24: {=SUM(INDIRECT(ADDRESS(income_min_row, COLUMN()) & ":" & ADDRESS(income_max_row, COLUMN())))} -> 0 | EB24: {=SUM(INDIRECT(ADDRESS(income_min_row, COLUMN()) & ":" & ADDRESS(income_max_row, COLUMN())))} -> 0 | EC24: {=SUM(INDIRECT(ADDRESS(income_min_row, COLUMN()) & ":" & ADDRESS(income_max_row, COLUMN())))} -> 0 | ED24: {=SUM(INDIRECT(ADDRESS(income_min_row, COLUMN()) & ":" & ADDRESS(income_max_row, COLUMN())))} -> 0 | EE24: {=SUM(INDIRECT(ADDRESS(income_min_row, COLUMN()) & ":" & ADDRESS(income_max_row, COLUMN())))} -> 0 | EF24: {=SUM(INDIRECT(ADDRESS(income_min_row, COLUMN()) & ":" & ADDRESS(income_max_row, COLUMN())))} -> 0 | EG24: {=SUM(INDIRECT(ADDRESS(income_min_row, COLUMN()) & ":" & ADDRESS(income_max_row, COLUMN())))} -> 0 | EH24: {=SUM(INDIRECT(ADDRESS(income_min_row, COLUMN()) & ":" & ADDRESS(income_max_row, COLUMN())))} -> 0 | ... EM24: {=SUM(INDIRECT(ADDRESS(income_min_row, COLUMN()) & ":" & ADDRESS(income_max_row, COLUMN())))} -> 0 | EO24: {=SUM(INDIRECT(ADDRESS(income_min_row, COLUMN()) & ":" & ADDRESS(income_max_row, COLUMN())))} -> 0 | EP24: {=SUM(INDIRECT(ADDRESS(income_min_row, COLUMN()) & ":" & ADDRESS(income_max_row, COLUMN())))} -> 0 | EQ24: {=SUM(INDIRECT(ADDRESS(income_min_row, COLUMN()) & ":" & ADDRESS(income_max_row, COLUMN())))} -> 0 | ER24: {=SUM(INDIRECT(ADDRESS(income_min_row, COLUMN()) & ":" & ADDRESS(income_max_row, COLUMN())))} -> 0 | ES24: {=SUM(INDIRECT(ADDRESS(income_min_row, COLUMN()) & ":" & ADDRESS(income_max_row, COLUMN())))} -> 0 | ET24: {=SUM(INDIRECT(ADDRESS(income_min_row, COLUMN()) & ":" & ADDRESS(income_max_row, COLUMN())))} -> 0 | EU24: {=SUM(INDIRECT(ADDRESS(income_min_row, COLUMN()) & ":" & ADDRESS(income_max_row, COLUMN())))} -> 0 | EV24: {=SUM(INDIRECT(ADDRESS(income_min_row, COLUMN()) & ":" & ADDRESS(income_max_row, COLUMN())))} -> 0 | ... FA24: {=SUM(INDIRECT(ADDRESS(income_min_row, COLUMN()) & ":" & ADDRESS(income_max_row, COLUMN())))} -> 0 | FC24: {=SUM(INDIRECT(ADDRESS(income_min_row, COLUMN()) & ":" & ADDRESS(income_max_row, COLUMN())))} -> 0 | FD24: {=SUM(INDIRECT(ADDRESS(income_min_row, COLUMN()) & ":" & ADDRESS(income_max_row, COLUMN())))} -> 0 | FE24: {=SUM(INDIRECT(ADDRESS(income_min_row, COLUMN()) & ":" & ADDRESS(income_max_row, COLUMN())))} -> 0 | FF24: {=SUM(INDIRECT(ADDRESS(income_min_row, COLUMN()) & ":" & ADDRESS(income_max_row, COLUMN())))} -> 0 | FG24: {=SUM(INDIRECT(ADDRESS(income_min_row, COLUMN()) & ":" & ADDRESS(income_max_row, COLUMN())))} -> 0 | FH24: {=SUM(INDIRECT(ADDRESS(income_min_row, COLUMN()) & ":" & ADDRESS(income_max_row, COLUMN())))} -> 0 | FI24: {=SUM(INDIRECT(ADDRESS(income_min_row, COLUMN()) & ":" & ADDRESS(income_max_row, COLUMN())))} -> 0 | FJ24: {=SUM(INDIRECT(ADDRESS(income_min_row, COLUMN()) & ":" & ADDRESS(income_max_row, COLUMN())))} -> 0 | ... FO24: {=SUM(INDIRECT(ADDRESS(income_min_row, COLUMN()) & ":" & ADDRESS(income_max_row, COLUMN())))} -> 0 | FQ24: {=SUM(INDIRECT(ADDRESS(income_min_row, COLUMN()) & ":" & ADDRESS(income_max_row, COLUMN())))} -> 0 | FR24: {=SUM(INDIRECT(ADDRESS(income_min_row, COLUMN()) & ":" & ADDRESS(income_max_row, COLUMN())))} -> 0 | FS24: {=SUM(INDIRECT(ADDRESS(income_min_row, COLUMN()) & ":" & ADDRESS(income_max_row, COLUMN())))} -> 0 | FT24: {=SUM(INDIRECT(ADDRESS(income_min_row, COLUMN()) & ":" & ADDRESS(income_max_row, COLUMN())))} -> 0 | FU24: {=SUM(INDIRECT(ADDRESS(income_min_row, COLUMN()) & ":" & ADDRESS(income_max_row, COLUMN())))} -> 0 | FV24: {=SUM(INDIRECT(ADDRESS(income_min_row, COLUMN()) & ":" & ADDRESS(income_max_row, COLUMN())))} -> 0 | FW24: {=SUM(INDIRECT(ADDRESS(income_min_row, COLUMN()) & ":" & ADDRESS(income_max_row, COLUMN())))} -> 0 | FX24: {=SUM(INDIRECT(ADDRESS(income_min_row, COLUMN()) & ":" & ADDRESS(income_max_row, COLUMN())))} -> 0 | ... GC24: {=SUM(INDIRECT(ADDRESS(income_min_row, COLUMN()) & ":" & ADDRESS(income_max_row, COLUMN())))} -> 0 | GE24: {=SUM(INDIRECT(ADDRESS(income_min_row, COLUMN()) & ":" & ADDRESS(income_max_row, COLUMN())))} -> 0 | GF24: {=SUM(INDIRECT(ADDRESS(income_min_row, COLUMN()) & ":" & ADDRESS(income_max_row, COLUMN())))} -> 0 | GG24: {=SUM(INDIRECT(ADDRESS(income_min_row, COLUMN()) & ":" & ADDRESS(income_max_row, COLUMN())))} -> 0 | GH24: {=SUM(INDIRECT(ADDRESS(income_min_row, COLUMN()) & ":" & ADDRESS(income_max_row, COLUMN())))} -> 0 | GI24: {=SUM(INDIRECT(ADDRESS(income_min_row, COLUMN()) & ":" & ADDRESS(income_max_row, COLUMN())))} -> 0 | GJ24: {=SUM(INDIRECT(ADDRESS(income_min_row, COLUMN()) & ":" & ADDRESS(income_max_row, COLUMN())))} -> 0 | GK24: {=SUM(INDIRECT(ADDRESS(income_min_row, COLUMN()) & ":" & ADDRESS(income_max_row, COLUMN())))} -> 0 | GL24: {=SUM(INDIRECT(ADDRESS(income_min_row, COLUMN()) & ":" & ADDRESS(income_max_row, COLUMN())))} -> 0 | ... GQ24: {=SUM(INDIRECT(ADDRESS(income_min_row, COLUMN()) & ":" & ADDRESS(income_max_row, COLUMN())))} -> 0 | GS24: {=SUM(INDIRECT(ADDRESS(income_min_row, COLUMN()) & ":" & ADDRESS(income_max_row, COLUMN())))} -> 0 | GT24: {=SUM(INDIRECT(ADDRESS(income_min_row, COLUMN()) & ":" & ADDRESS(income_max_row, COLUMN())))} -> 0 | GU24: {=SUM(INDIRECT(ADDRESS(income_min_row, COLUMN()) & ":" & ADDRESS(income_max_row, COLUMN())))} -> 0 | GV24: {=SUM(INDIRECT(ADDRESS(income_min_row, COLUMN()) & ":" & ADDRESS(income_max_row, COLUMN())))} -> 0 | GW24: {=SUM(INDIRECT(ADDRESS(income_min_row, COLUMN()) & ":" & ADDRESS(income_max_row, COLUMN())))} -> 0 | GX24: {=SUM(INDIRECT(ADDRESS(income_min_row, COLUMN()) & ":" & ADDRESS(income_max_row, COLUMN())))} -> 0 | GY24: {=SUM(INDIRECT(ADDRESS(income_min_row, COLUMN()) & ":" & ADDRESS(income_max_row, COLUMN())))} -> 0 | GZ24: {=SUM(INDIRECT(ADDRESS(income_min_row, COLUMN()) & ":" & ADDRESS(income_max_row, COLUMN())))} -> 0 | ... HE24: {=SUM(INDIRECT(ADDRESS(income_min_row, COLUMN()) & ":" & ADDRESS(income_max_row, COLUMN())))} -> 0 | HG24: {=SUM(INDIRECT(ADDRESS(income_min_row, COLUMN()) & ":" & ADDRESS(income_max_row, COLUMN())))} -> 0 | HH24: {=SUM(INDIRECT(ADDRESS(income_min_row, COLUMN()) & ":" & ADDRESS(income_max_row, COLUMN())))} -> 0 | HI24: {=SUM(INDIRECT(ADDRESS(income_min_row, COLUMN()) & ":" & ADDRESS(income_max_row, COLUMN())))} -> 0 | HJ24: {=SUM(INDIRECT(ADDRESS(income_min_row, COLUMN()) & ":" & ADDRESS(income_max_row, COLUMN())))} -> 0 | HK24: {=SUM(INDIRECT(ADDRESS(income_min_row, COLUMN()) & ":" & ADDRESS(income_max_row, COLUMN())))} -> 0 | HL24: {=SUM(INDIRECT(ADDRESS(income_min_row, COLUMN()) & ":" & ADDRESS(income_max_row, COLUMN())))} -> 0 | HM24: {=SUM(INDIRECT(ADDRESS(income_min_row, COLUMN()) & ":" & ADDRESS(income_max_row, COLUMN())))} -> 0 | HN24: {=SUM(INDIRECT(ADDRESS(income_min_row, COLUMN()) & ":" & ADDRESS(income_max_row, COLUMN())))} -> 0 | ... HS24: {=SUM(INDIRECT(ADDRESS(income_min_row, COLUMN()) & ":" & ADDRESS(income_max_row, COLUMN())))} -> 0 | HU24: {=SUM(INDIRECT(ADDRESS(income_min_row, COLUMN()) & ":" & ADDRESS(income_max_row, COLUMN())))} -> 0 | HV24: {=SUM(INDIRECT(ADDRESS(income_min_row, COLUMN()) & ":" & ADDRESS(income_max_row, COLUMN())))} -> 0 | HW24: {=SUM(INDIRECT(ADDRESS(income_min_row, COLUMN()) & ":" & ADDRESS(income_max_row, COLUMN())))} -> 0 | HX24: {=SUM(INDIRECT(ADDRESS(income_min_row, COLUMN()) & ":" & ADDRESS(income_max_row, COLUMN())))} -> 0 | HY24: {=SUM(INDIRECT(ADDRESS(income_min_row, COLUMN()) & ":" & ADDRESS(income_max_row, COLUMN())))} -> 0 | HZ24: {=SUM(INDIRECT(ADDRESS(income_min_row, COLUMN()) & ":" & ADDRESS(income_max_row, COLUMN())))} -> 0 | IA24: {=SUM(INDIRECT(ADDRESS(income_min_row, COLUMN()) & ":" & ADDRESS(income_max_row, COLUMN())))} -> 0 | IB24: {=SUM(INDIRECT(ADDRESS(income_min_row, COLUMN()) & ":" & ADDRESS(income_max_row, COLUMN())))} -> 0 | ... IG24: {=SUM(INDIRECT(ADDRESS(income_min_row, COLUMN()) & ":" & ADDRESS(income_max_row, COLUMN())))} -> 0
